<?xml version="1.0"?>
	<robot name="P3AT">
		<link name="Pioneer3AT/base_link">
			<visual>
				<geometry>
					<mesh filename="package://rviz_test/meshes/chassis.stl"/>
				</geometry>
				
				<origin xyz="0 0 0.177" rpy="0 0 0"/>
				
				<material name="ChassisRed">
					<color rgba="0.851 0.0 0.0 1.0"/>
				</material>
			</visual>
		</link>


<link name="top_plate">
		<visual>
			<origin xyz="0 0 0" rpy="0 0 0"/>
			<geometry>
				<mesh filename="package://rviz_test/meshes/top.stl"/>
			</geometry>
			<material name="TopBlack">
					<color rgba="0.038 0.038 0.038 1.0"/>
			</material>
		</visual>
	</link>

	<joint name="base_top_joint" type="fixed">
		<origin xyz="0.003 0 0.274" rpy="0 0 0"/>
		<parent link="Pioneer3AT/base_link"/>
		<child link="top_plate"/>
	</joint>






		<link name="front_left_axle">
		      <visual>
			<origin xyz="0 0 0" rpy="0 0 0"/>
			<geometry>
				<mesh filename="package://rviz_test/meshes/axle.stl"/>
			</geometry>
			<material name="AxleGrey">
				<color rgba="0.5 0.5 0.5 1"/>
			</material>
		      </visual>
	  	</link>
		<joint name="front_left_axle_joint" type="continuous">
		  <origin xyz="0.01755 0.0312 0.111" rpy="0 0 0"/>
		  <parent link="Pioneer3AT/base_link"/>
		  <child link="front_left_axle"/>
		  <axis xyz="0 1 0" />
	      </joint>







		
		
		<link name="front_left">
			<visual>
				<origin xyz="0.13 0.20 0.10" rpy="0 5.5 0"/>
				<geometry>
						<mesh filename="package://rviz_test/meshes/wheel.stl"/>
				</geometry>
				<material name="WheelBlack">
					<color rgba="0.117 0.117 0.117 1"/>
				</material>
			</visual>
		</link>
		
		<link name="front_right">
			<visual>
				<origin xyz="0.13 -0.20 0.10" rpy="0 1.5 0"/>
				<geometry>
						<mesh filename="package://rviz_test/meshes/wheel.stl"/>
				</geometry>
				<material name="WheelBlack">
					<color rgba="0.117 0.117 0.117 1"/>
				</material>
			</visual>
		</link>
		
		<link name="rear_left">
			<visual>
				<origin xyz="-0.13 0.20 0.10" rpy="0 0.5 0"/>
				<geometry>
						<mesh filename="package://rviz_test/meshes/wheel.stl"/>
				</geometry>
				<material name="WheelBlack">
					<color rgba="0.117 0.117 0.117 1"/>
				</material>
			</visual>
		</link>
		
		<link name="rear_right">
			<visual>
				<origin xyz="-0.13 -0.20 0.10" rpy="0 1.5 0"/>
				<geometry>
						<mesh filename="package://rviz_test/meshes/wheel.stl"/>
				</geometry>
				<material name="WheelBlack">
					<color rgba="0.117 0.117 0.117 1"/>
				</material>
			</visual>
		</link>
		
		

		<joint name="base_to_wheel1" type="fixed">
			<parent link="Pioneer3AT/base_link"/>
				<child link="front_left"/>
					<origin xyz="0 0 0"/>
		</joint>
		
		<joint name="base_to_wheel2" type="fixed">
			<parent link="Pioneer3AT/base_link"/>
				<child link="front_right"/>
				<origin xyz="0 0 0"/>
		</joint>
		
		<joint name="base_to_wheel3" type="fixed">
			<parent link="Pioneer3AT/base_link"/>
				<child link="rear_left"/>
				<origin xyz="0 0 0"/>
		</joint>
		
		<joint name="base_to_wheel4" type="fixed">
			<parent link="Pioneer3AT/base_link"/>
				<child link="rear_right"/>
				<origin xyz="0 0 0"/>
		</joint>
</robot>
