<?xml version="1.0" ?>
<!-- =================================================================================== -->
<!-- |    This document was autogenerated by xacro from rviz_test.xacro               | -->
<!-- |    EDITING THIS FILE BY HAND IS NOT RECOMMENDED                                 | -->
<!-- =================================================================================== -->
<!-- Please note that this URDF will _not_ load in gazebo -->
<robot name="rviz_test" xmlns:controller="http://playerstage.sourceforge.net/gazebo/xmlschema/#controller" xmlns:interface="http://playerstage.sourceforge.net/gazebo/xmlschema/#interface" xmlns:sensor="http://playerstage.sourceforge.net/gazebo/xmlschema/#sensor" xmlns:xacro="http://ros.org/wiki/xacro">
  <!-- Chassis -->
  <link name="base_link">
    <visual>
      <origin rpy="0 0 0" xyz="0 0 0.177"/>
      <geometry>
        <mesh filename="package://rviz_test/meshes/chassis.stl"/>
      </geometry>
      <material name="ChassisRed">
        <color rgba="0.851 0.0 0.0 1.0"/>
      </material>
    </visual>
  </link>
  <!-- Top -->
  <link name="top_plate">
    <visual>
      <origin rpy="0 0 0" xyz="0 0 0"/>
      <geometry>
        <mesh filename="package://rviz_test/meshes/top.stl"/>
      </geometry>
      <material name="TopBlack">
        <color rgba="0.038 0.038 0.038 1.0"/>
      </material>
    </visual>
  </link>
  <joint name="base_top_joint" type="fixed">
    <origin rpy="0 0 0" xyz="0.003 0 0.274"/>
    <parent link="base_link"/>
    <child link="top_plate"/>
  </joint>
  <!-- Axle~Hub~Wheel  -->
  <link name="front_left_axle">
    <visual>
      <origin rpy="0 0 0" xyz="0 0 0"/>
      <geometry>
        <mesh filename="package://rviz_test/meshes/axle.stl"/>
      </geometry>
      <material name="AxleGrey">
        <color rgba="0.5 0.5 0.5 1"/>
      </material>
    </visual>
  </link>
  <joint name="front_left_axle_joint" type="continuous">
    <origin rpy="0 0 0" xyz="0.135 0.156 0.111"/>
    <parent link="base_link"/>
    <child link="front_left_axle"/>
    <axis xyz="0 1 0"/>
  </joint>
  <link name="front_left_hub">
    <visual>
      <origin rpy="0.0 0 0" xyz="0 0 0"/>
      <geometry>
        <mesh filename="package://rviz_test/meshes/hub.stl"/>
      </geometry>
      <material name="HubcapYellow">
        <color rgba="1.0 0.811 0.151 1.0"/>
      </material>
    </visual>
  </link>
  <joint name="front_left_hub_joint" type="fixed">
    <origin rpy="0 0 0" xyz="0 0.041 0"/>
    <parent link="front_left_axle"/>
    <child link="front_left_hub"/>
  </joint>
  <link name="front_left_wheel">
    <visual>
      <origin rpy="0 0 0" xyz="0 0 0"/>
      <geometry>
        <mesh filename="package://rviz_test/meshes/wheel.stl"/>
      </geometry>
      <material name="WheelBlack">
        <color rgba="0.117 0.117 0.117 1"/>
      </material>
    </visual>
  </link>
  <joint name="front_left_wheel_joint" type="fixed">
    <origin rpy="0 0 0" xyz="0 0 0"/>
    <parent link="front_left_hub"/>
    <child link="front_left_wheel"/>
  </joint>
  <link name="front_right_axle">
    <visual>
      <origin rpy="0 0 0" xyz="0 0 0"/>
      <geometry>
        <mesh filename="package://rviz_test/meshes/axle.stl"/>
      </geometry>
      <material name="AxleGrey">
        <color rgba="0.5 0.5 0.5 1"/>
      </material>
    </visual>
  </link>
  <joint name="front_right_axle_joint" type="continuous">
    <origin rpy="0 0 0" xyz="0.135 -0.156 0.111"/>
    <parent link="base_link"/>
    <child link="front_right_axle"/>
    <axis xyz="0 1 0"/>
  </joint>
  <link name="front_right_hub">
    <visual>
      <origin rpy="-3.14 0 0" xyz="0 0 0"/>
      <geometry>
        <mesh filename="package://rviz_test/meshes/hub.stl"/>
      </geometry>
      <material name="HubcapYellow">
        <color rgba="1.0 0.811 0.151 1.0"/>
      </material>
    </visual>
  </link>
  <joint name="front_right_hub_joint" type="fixed">
    <origin rpy="0 0 0" xyz="0 -0.041 0"/>
    <parent link="front_right_axle"/>
    <child link="front_right_hub"/>
  </joint>
  <link name="front_right_wheel">
    <visual>
      <origin rpy="0 0 0" xyz="0 0 0"/>
      <geometry>
        <mesh filename="package://rviz_test/meshes/wheel.stl"/>
      </geometry>
      <material name="WheelBlack">
        <color rgba="0.117 0.117 0.117 1"/>
      </material>
    </visual>
  </link>
  <joint name="front_right_wheel_joint" type="fixed">
    <origin rpy="0 0 0" xyz="0 0 0"/>
    <parent link="front_right_hub"/>
    <child link="front_right_wheel"/>
  </joint>
  <link name="rear_left_axle">
    <visual>
      <origin rpy="0 0 0" xyz="0 0 0"/>
      <geometry>
        <mesh filename="package://rviz_test/meshes/axle.stl"/>
      </geometry>
      <material name="AxleGrey">
        <color rgba="0.5 0.5 0.5 1"/>
      </material>
    </visual>
  </link>
  <joint name="rear_left_axle_joint" type="continuous">
    <origin rpy="0 0 0" xyz="-0.135 0.156 0.111"/>
    <parent link="base_link"/>
    <child link="rear_left_axle"/>
    <axis xyz="0 1 0"/>
  </joint>
  <link name="rear_left_hub">
    <visual>
      <origin rpy="0.0 0 0" xyz="0 0 0"/>
      <geometry>
        <mesh filename="package://rviz_test/meshes/hub.stl"/>
      </geometry>
      <material name="HubcapYellow">
        <color rgba="1.0 0.811 0.151 1.0"/>
      </material>
    </visual>
  </link>
  <joint name="rear_left_hub_joint" type="fixed">
    <origin rpy="0 0 0" xyz="0 0.041 0"/>
    <parent link="rear_left_axle"/>
    <child link="rear_left_hub"/>
  </joint>
  <link name="rear_left_wheel">
    <visual>
      <origin rpy="0 0 0" xyz="0 0 0"/>
      <geometry>
        <mesh filename="package://rviz_test/meshes/wheel.stl"/>
      </geometry>
      <material name="WheelBlack">
        <color rgba="0.117 0.117 0.117 1"/>
      </material>
    </visual>
  </link>
  <joint name="rear_left_wheel_joint" type="fixed">
    <origin rpy="0 0 0" xyz="0 0 0"/>
    <parent link="rear_left_hub"/>
    <child link="rear_left_wheel"/>
  </joint>
  <link name="rear_right_axle">
    <visual>
      <origin rpy="0 0 0" xyz="0 0 0"/>
      <geometry>
        <mesh filename="package://rviz_test/meshes/axle.stl"/>
      </geometry>
      <material name="AxleGrey">
        <color rgba="0.5 0.5 0.5 1"/>
      </material>
    </visual>
  </link>
  <joint name="rear_right_axle_joint" type="continuous">
    <origin rpy="0 0 0" xyz="-0.135 -0.156 0.111"/>
    <parent link="base_link"/>
    <child link="rear_right_axle"/>
    <axis xyz="0 1 0"/>
  </joint>
  <link name="rear_right_hub">
    <visual>
      <origin rpy="-3.14 0 0" xyz="0 0 0"/>
      <geometry>
        <mesh filename="package://rviz_test/meshes/hub.stl"/>
      </geometry>
      <material name="HubcapYellow">
        <color rgba="1.0 0.811 0.151 1.0"/>
      </material>
    </visual>
  </link>
  <joint name="rear_right_hub_joint" type="fixed">
    <origin rpy="0 0 0" xyz="0 -0.041 0"/>
    <parent link="rear_right_axle"/>
    <child link="rear_right_hub"/>
  </joint>
  <link name="rear_right_wheel">
    <visual>
      <origin rpy="0 0 0" xyz="0 0 0"/>
      <geometry>
        <mesh filename="package://rviz_test/meshes/wheel.stl"/>
      </geometry>
      <material name="WheelBlack">
        <color rgba="0.117 0.117 0.117 1"/>
      </material>
    </visual>
  </link>
  <joint name="rear_right_wheel_joint" type="fixed">
    <origin rpy="0 0 0" xyz="0 0 0"/>
    <parent link="rear_right_hub"/>
    <child link="rear_right_wheel"/>
  </joint>
  <!-- Sonar -->
  <link name="front_sonar">
    <visual>
      <origin rpy="0 0 0" xyz="0 0 0"/>
      <geometry>
        <mesh filename="package://rviz_test/meshes/front_sonar.stl"/>
      </geometry>
      <material name="SonarYellow">
        <color rgba="0.715 0.583 0.210 1.0"/>
      </material>
    </visual>
  </link>
  <joint name="front_sonar_joint" type="fixed">
    <origin rpy="0 0 0" xyz="0.193 0 0.25"/>
    <parent link="base_link"/>
    <child link="front_sonar"/>
  </joint>
  <link name="rear_sonar">
    <visual>
      <origin rpy="0 0 0" xyz="0 0 0"/>
      <geometry>
        <mesh filename="package://rviz_test/meshes/back_sonar.stl"/>
      </geometry>
      <material name="SonarYellow">
        <color rgba="0.715 0.583 0.210 1.0"/>
      </material>
    </visual>
  </link>
  <joint name="rear_sonar_joint" type="fixed">
    <origin rpy="0 0 0" xyz="-0.187 0 0.247"/>
    <parent link="base_link"/>
    <child link="rear_sonar"/>
  </joint>
  <!-- Sonar offsets came from p2os_driver robot_params.cc -->
  <!-- Not used, a lot of TF clutter
  <xacro:Sonar id="1"  px="0.145"  py="0.13"   rz="1.5705"/>
  <xacro:Sonar id="2"  px="0.185"  py="0.115"  rz="0.8725"/>
  <xacro:Sonar id="3"  px="0.22"   py="0.08"   rz="0.5235"/>
  <xacro:Sonar id="4"  px="0.24"   py="0.025"  rz="0.1745"/>
  <xacro:Sonar id="5"  px="0.24"   py="-0.025" rz="-0.1745"/>
  <xacro:Sonar id="6"  px="0.22"   py="-0.08"  rz="-0.5235"/>
  <xacro:Sonar id="7"  px="0.185"  py="-0.115" rz="-0.8725"/>
  <xacro:Sonar id="8"  px="0.145"  py="-0.13"  rz="-1.5705"/>
  <xacro:Sonar id="9"  px="-0.145" py="-0.13"  rz="-1.5705"/>
  <xacro:Sonar id="10" px="-0.185" py="-0.115" rz="-2.2685"/>
  <xacro:Sonar id="11" px="-0.22"  py="-0.08"  rz="-2.6175"/>
  <xacro:Sonar id="12" px="-0.24"  py="-0.025" rz="-2.9665"/>
  <xacro:Sonar id="13" px="-0.24"  py="0.025"  rz="2.9665"/>
  <xacro:Sonar id="14" px="-0.22"  py="0.08"   rz="2.6175"/>
  <xacro:Sonar id="15" px="-0.185" py="0.115"  rz="2.2685"/>
  <xacro:Sonar id="16" px="-0.145" py="0.13"   rz="1.5705"/>
-->
</robot>

